import {
  MyAwesomeError,
  rejectCustomError,
  resolveValue,
  throwCustomError,
  throwError,
} from '03-error-handling-async';

describe('resolveValue', () => {
  test('should resolve provided value', async () => {
    const value = 42;
    const result = await resolveValue(value);
    expect(result).toBe(value);
  });
});

describe('throwError', () => {
  test('should throw error with provided message', () => {
    const errorMessage = 'This is a test error';
    expect(() => throwError(errorMessage)).toThrow(errorMessage);
  });

  test('should throw error with default message if message is not provided', () => {
    expect(() => throwError()).toThrow('Oops!');
  });
});

describe('throwCustomError', () => {
  test('should throw custom error', () => {
    expect(() => throwCustomError()).toThrow(MyAwesomeError);
    expect(() => throwCustomError()).toThrow(
      'This is my awesome custom error!',
    );
  });
});

describe('rejectCustomError', () => {
  test('should reject custom error', async () => {
    await expect(rejectCustomError()).rejects.toThrow(MyAwesomeError);
    await expect(rejectCustomError()).rejects.toThrow(
      'This is my awesome custom error!',
    );
  });
});
